2022-07-08 11:06:42,177 | INFO | Tests skipped
2022-07-08 11:06:42,178 | INFO | Check successful
2022-07-08 11:06:42,356 | ERROR | The following unhandled exception occured in Root :
Traceback (most recent call last):
  File "c:\users\tojak\source\repos\labeq-exopy\src\labeq_exopy\instruments\drivers\visa_tools.py", line 100, in open_connection
    self._driver = rm.open_resource(self.connection_str,
  File "C:\Users\tojak\anaconda3\envs\labeq\lib\site-packages\pyvisa\highlevel.py", line 3284, in open_resource
    res.open(access_mode, open_timeout)
  File "C:\Users\tojak\anaconda3\envs\labeq\lib\site-packages\pyvisa\resources\resource.py", line 278, in open
    self.session, status = self._resource_manager.open_bare_resource(
  File "C:\Users\tojak\anaconda3\envs\labeq\lib\site-packages\pyvisa\highlevel.py", line 3209, in open_bare_resource
    return self.visalib.open(self.session, resource_name, access_mode, open_timeout)
  File "C:\Users\tojak\anaconda3\envs\labeq\lib\site-packages\pyvisa\ctwrapper\functions.py", line 1851, in open
    ret = library.viOpen(
  File "C:\Users\tojak\anaconda3\envs\labeq\lib\site-packages\pyvisa\ctwrapper\highlevel.py", line 226, in _return_handler
    return self.handle_return_value(session, ret_value)  # type: ignore
  File "C:\Users\tojak\anaconda3\envs\labeq\lib\site-packages\pyvisa\highlevel.py", line 251, in handle_return_value
    raise errors.VisaIOError(rv)
pyvisa.errors.VisaIOError: VI_ERROR_RSRC_NFOUND (-1073807343): Insufficient location information or the requested device or resource is not present in the system.

During handling of the above exception, another exception occurred:

Traceback (most recent call last):
  File "C:\Users\tojak\anaconda3\envs\labeq\lib\site-packages\exopy\tasks\tasks\decorators.py", line 105, in decorator
    return function_to_decorate(*args, **kwargs)
  File "C:\Users\tojak\anaconda3\envs\labeq\lib\site-packages\exopy\tasks\tasks\base_tasks.py", line 1140, in perform
    self.prepare()
  File "C:\Users\tojak\anaconda3\envs\labeq\lib\site-packages\exopy\tasks\tasks\base_tasks.py", line 1179, in prepare
    super().prepare()
  File "C:\Users\tojak\anaconda3\envs\labeq\lib\site-packages\exopy\tasks\tasks\base_tasks.py", line 706, in prepare
    child.prepare()
  File "C:\Users\tojak\anaconda3\envs\labeq\lib\site-packages\exopy\tasks\tasks\task_interface.py", line 64, in prepare
    super(InterfaceableMixin, self).prepare()
  File "C:\Users\tojak\anaconda3\envs\labeq\lib\site-packages\exopy\tasks\tasks\instr_task.py", line 108, in prepare
    self.start_driver()
  File "C:\Users\tojak\anaconda3\envs\labeq\lib\site-packages\exopy\tasks\tasks\instr_task.py", line 123, in start_driver
    self.driver = starter.start(d_cls,
  File "c:\users\tojak\source\repos\labeq-exopy\src\labeq_exopy\instruments\starters\legacy_starter.py", line 26, in start
    return driver_cls(c)
  File "c:\users\tojak\source\repos\labeq-exopy\src\labeq_exopy\instruments\drivers\visa_tools.py", line 92, in __init__
    self.open_connection()
  File "c:\users\tojak\source\repos\labeq-exopy\src\labeq_exopy\instruments\drivers\visa\KeithleyDMM6500DigitMultimeter_driver.py", line 24, in open_connection
    super(Keithley6500, self).open_connection(**para)
  File "c:\users\tojak\source\repos\labeq-exopy\src\labeq_exopy\instruments\drivers\visa_tools.py", line 104, in open_connection
    raise InstrIOError(str(er))
labeq_exopy.instruments.drivers.driver_tools.InstrIOError: VI_ERROR_RSRC_NFOUND (-1073807343): Insufficient location information or the requested device or resource is not present in the system.
2022-07-08 11:06:44,376 | INFO | Process shuting down
