2022-07-08 15:43:28,165 | INFO | Check successful
2022-07-08 15:43:28,262 | INFO | 0.1
2022-07-08 15:43:28,267 | INFO | range val: 0.001
2022-07-08 15:43:28,278 | ERROR | The following unhandled exception occured :
Traceback (most recent call last):
  File "C:\Users\tojak\anaconda3\envs\labeq\lib\site-packages\exopy\tasks\tasks\base_tasks.py", line 1148, in perform
    child.perform_()
  File "C:\Users\tojak\anaconda3\envs\labeq\lib\site-packages\exopy\tasks\tasks\decorators.py", line 86, in decorator
    return function_to_decorate(*args, **kwargs)
  File "c:\users\tojak\source\repos\labeq-exopy\src\labeq_exopy\tasks\tasks\instr\yokogawaGS200_tasks.py", line 72, in perform
    self.write_in_database('set_Range', value)
  File "C:\Users\tojak\anaconda3\envs\labeq\lib\site-packages\exopy\tasks\tasks\base_tasks.py", line 355, in write_in_database
    return self.database.set_value(self.path, value_name, value)
  File "C:\Users\tojak\anaconda3\envs\labeq\lib\site-packages\exopy\tasks\tasks\database.py", line 104, in set_value
    index = self._entry_index_map[full_path]
KeyError: 'root/Strickland_set_Range'
2022-07-08 15:43:30,299 | INFO | Process shuting down
