2022-07-08 10:57:36,085 | INFO | Check successful
2022-07-08 10:57:36,199 | INFO | Iterating connection 0/2 for instrument YokogawaGS200
2022-07-08 10:57:36,250 | INFO | Iterating connection 1/2 for instrument YokogawaGS200
2022-07-08 10:57:36,292 | ERROR | The following unhandled exception occured :
Traceback (most recent call last):
  File "C:\Users\tojak\anaconda3\envs\labeq\lib\site-packages\exopy\tasks\tasks\base_tasks.py", line 1148, in perform
    child.perform_()
  File "C:\Users\tojak\anaconda3\envs\labeq\lib\site-packages\exopy\tasks\tasks\decorators.py", line 86, in decorator
    return function_to_decorate(*args, **kwargs)
  File "C:\Users\tojak\anaconda3\envs\labeq\lib\site-packages\exopy\tasks\tasks\decorators.py", line 307, in wrapper
    return perform(obj, *args, **kwargs)
  File "c:\users\tojak\source\repos\labeq-exopy\src\labeq_exopy\tasks\tasks\instr\source_dccurrent_tasks.py", line 44, in perform
    self.driver.source_current_dc(value)
  File "c:\users\tojak\source\repos\labeq-exopy\src\labeq_exopy\instruments\drivers\driver_tools.py", line 126, in wrapper
    return method(self, *args, **kwargs)
  File "c:\users\tojak\source\repos\labeq-exopy\src\labeq_exopy\instruments\drivers\visa\yokogawa.py", line 54, in source_current_dc
    setSource(self,value)
  File "c:\users\tojak\source\repos\labeq-exopy\src\labeq_exopy\instruments\drivers\visa\yokogawa.py", line 40, in setSource
    raise InstrIOError('Instrument did not set correctly the voltage')
labeq_exopy.instruments.drivers.driver_tools.InstrIOError: Instrument did not set correctly the voltage
2022-07-08 10:57:38,299 | INFO | Process shuting down
