2022-07-02 16:00:32,172 | INFO | Check successful
2022-07-02 16:00:34,195 | INFO | Iterating connection 0/2 for instrument GWINSTEK1054B
2022-07-02 16:00:36,221 | INFO | Iterating connection 1/2 for instrument GWINSTEK1054B
2022-07-02 16:00:38,246 | ERROR | The following unhandled exception occured :
Traceback (most recent call last):
  File "C:\Users\tojak\anaconda3\envs\labeq\lib\site-packages\exopy\tasks\tasks\base_tasks.py", line 1148, in perform
    child.perform_()
  File "C:\Users\tojak\anaconda3\envs\labeq\lib\site-packages\exopy\tasks\tasks\decorators.py", line 86, in decorator
    return function_to_decorate(*args, **kwargs)
  File "C:\Users\tojak\anaconda3\envs\labeq\lib\site-packages\exopy\tasks\tasks\decorators.py", line 307, in wrapper
    return perform(obj, *args, **kwargs)
  File "c:\users\tojak\source\repos\labeq-exopy\src\labeq_exopy\tasks\tasks\instr\GWINSTEK1054B_tasks.py", line 28, in perform
    value = self.driver.read_mean()
  File "c:\users\tojak\source\repos\labeq-exopy\src\labeq_exopy\instruments\drivers\driver_tools.py", line 126, in wrapper
    return method(self, *args, **kwargs)
  File "c:\users\tojak\source\repos\labeq-exopy\src\labeq_exopy\instruments\drivers\visa\GWINSTEK1054BOscilloscope_driver.py", line 56, in read_mean
    print(self.query('sens:func?'))
  File "c:\users\tojak\source\repos\labeq-exopy\src\labeq_exopy\instruments\drivers\visa_tools.py", line 183, in query
    return self._driver.query(message)
  File "C:\Users\tojak\anaconda3\envs\labeq\lib\site-packages\pyvisa\resources\messagebased.py", line 648, in query
    return self.read()
  File "C:\Users\tojak\anaconda3\envs\labeq\lib\site-packages\pyvisa\resources\messagebased.py", line 486, in read
    message = self._read_raw().decode(enco)
  File "C:\Users\tojak\anaconda3\envs\labeq\lib\site-packages\pyvisa\resources\messagebased.py", line 442, in _read_raw
    chunk, status = self.visalib.read(self.session, size)
  File "C:\Users\tojak\anaconda3\envs\labeq\lib\site-packages\pyvisa\ctwrapper\functions.py", line 2337, in read
    ret = library.viRead(session, buffer, count, byref(return_count))
  File "C:\Users\tojak\anaconda3\envs\labeq\lib\site-packages\pyvisa\ctwrapper\highlevel.py", line 226, in _return_handler
    return self.handle_return_value(session, ret_value)  # type: ignore
  File "C:\Users\tojak\anaconda3\envs\labeq\lib\site-packages\pyvisa\highlevel.py", line 251, in handle_return_value
    raise errors.VisaIOError(rv)
pyvisa.errors.VisaIOError: VI_ERROR_TMO (-1073807339): Timeout expired before operation completed.
2022-07-02 16:00:40,276 | INFO | Process shuting down
