2022-07-01 15:05:48,435 | INFO | Check successful
2022-07-01 15:05:48,454 | CRITICAL | C:\Users\tojak\anaconda3\envs\labeq\lib\site-packages\pyvisa\resources\messagebased.py:642: UserWarning: write message already ends with termination characters
  self.write(message)
2022-07-01 15:05:48,454 | INFO | Iterating connection 0/2 for instrument Keithley6500
2022-07-01 15:05:48,474 | INFO | Iterating connection 1/2 for instrument Keithley6500
2022-07-01 15:05:48,492 | INFO | Iterating connection 0/2 for instrument Keithley6500
2022-07-01 15:05:48,511 | INFO | Iterating connection 0/2 for instrument Keithley6500
2022-07-01 15:05:48,531 | INFO | Iterating connection 1/2 for instrument Keithley6500
2022-07-01 15:05:48,556 | INFO | Iterating connection 1/2 for instrument Keithley6500
2022-07-01 15:05:48,578 | INFO | Iterating connection 0/2 for instrument Keithley6500
2022-07-01 15:05:48,598 | INFO | Iterating connection 1/2 for instrument Keithley6500
2022-07-01 15:05:48,622 | ERROR | The following unhandled exception occured :
Traceback (most recent call last):
  File "c:\users\tojak\source\repos\labeq-exopy\src\labeq_exopy\instruments\drivers\driver_tools.py", line 79, in __get__
    return obj._cache[name]
KeyError: 'function'

During handling of the above exception, another exception occurred:

Traceback (most recent call last):
  File "C:\Users\tojak\anaconda3\envs\labeq\lib\site-packages\exopy\tasks\tasks\base_tasks.py", line 1148, in perform
    child.perform_()
  File "C:\Users\tojak\anaconda3\envs\labeq\lib\site-packages\exopy\tasks\tasks\decorators.py", line 86, in decorator
    return function_to_decorate(*args, **kwargs)
  File "C:\Users\tojak\anaconda3\envs\labeq\lib\site-packages\exopy\tasks\tasks\decorators.py", line 307, in wrapper
    return perform(obj, *args, **kwargs)
  File "c:\users\tojak\source\repos\labeq-exopy\src\labeq_exopy\tasks\tasks\instr\meas_dc_tasks.py", line 39, in perform
    value = self.driver.read_voltage_dc()
  File "c:\users\tojak\source\repos\labeq-exopy\src\labeq_exopy\instruments\drivers\driver_tools.py", line 126, in wrapper
    return method(self, *args, **kwargs)
  File "c:\users\tojak\source\repos\labeq-exopy\src\labeq_exopy\instruments\drivers\visa\KeithleyDMM6500DigitMultimeter_driver.py", line 102, in read_voltage_dc
    if self.function != 'VOLT:DC\n':
  File "c:\users\tojak\source\repos\labeq-exopy\src\labeq_exopy\instruments\drivers\driver_tools.py", line 81, in __get__
    aux = super(instrument_property, self).__get__(obj,
  File "c:\users\tojak\source\repos\labeq-exopy\src\labeq_exopy\instruments\drivers\driver_tools.py", line 126, in wrapper
    return method(self, *args, **kwargs)
  File "c:\users\tojak\source\repos\labeq-exopy\src\labeq_exopy\instruments\drivers\visa\KeithleyDMM6500DigitMultimeter_driver.py", line 74, in function
    value = self.query('FUNCtion?\n')
  File "c:\users\tojak\source\repos\labeq-exopy\src\labeq_exopy\instruments\drivers\visa_tools.py", line 183, in query
    return self._driver.query(message)
  File "C:\Users\tojak\anaconda3\envs\labeq\lib\site-packages\pyvisa\resources\messagebased.py", line 648, in query
    return self.read()
  File "C:\Users\tojak\anaconda3\envs\labeq\lib\site-packages\pyvisa\resources\messagebased.py", line 486, in read
    message = self._read_raw().decode(enco)
  File "C:\Users\tojak\anaconda3\envs\labeq\lib\site-packages\pyvisa\resources\messagebased.py", line 442, in _read_raw
    chunk, status = self.visalib.read(self.session, size)
  File "C:\Users\tojak\anaconda3\envs\labeq\lib\site-packages\pyvisa\ctwrapper\functions.py", line 2337, in read
    ret = library.viRead(session, buffer, count, byref(return_count))
  File "C:\Users\tojak\anaconda3\envs\labeq\lib\site-packages\pyvisa\ctwrapper\highlevel.py", line 226, in _return_handler
    return self.handle_return_value(session, ret_value)  # type: ignore
  File "C:\Users\tojak\anaconda3\envs\labeq\lib\site-packages\pyvisa\highlevel.py", line 251, in handle_return_value
    raise errors.VisaIOError(rv)
pyvisa.errors.VisaIOError: VI_ERROR_IO (-1073807298): Could not perform operation because of I/O error.
2022-07-01 15:05:50,637 | INFO | Process shuting down
