2022-07-01 16:21:13,219 | INFO | Check successful
2022-07-01 16:21:13,298 | INFO | value : -3.931597E-06
2022-07-01 16:21:13,299 | ERROR | The following unhandled exception occured :
Traceback (most recent call last):
  File "C:\Users\tojak\anaconda3\envs\labeq\lib\site-packages\exopy\tasks\tasks\base_tasks.py", line 1148, in perform
    child.perform_()
  File "C:\Users\tojak\anaconda3\envs\labeq\lib\site-packages\exopy\tasks\tasks\decorators.py", line 86, in decorator
    return function_to_decorate(*args, **kwargs)
  File "C:\Users\tojak\anaconda3\envs\labeq\lib\site-packages\exopy\tasks\tasks\decorators.py", line 307, in wrapper
    return perform(obj, *args, **kwargs)
  File "C:\Users\tojak\anaconda3\envs\labeq\lib\site-packages\exopy\tasks\tasks\task_interface.py", line 84, in perform
    return self.interface.perform(*args, **kwargs)
  File "c:\users\tojak\source\repos\labeq-exopy\src\labeq_exopy\tasks\tasks\instr\meas_two_res_tasks.py", line 64, in perform
    value = self.task.driver.read_two_resistance(arg_list)
  File "c:\users\tojak\source\repos\labeq-exopy\src\labeq_exopy\instruments\drivers\driver_tools.py", line 126, in wrapper
    return method(self, *args, **kwargs)
TypeError: Keithley6500.read_two_resistance() takes 1 positional argument but 2 were given
2022-07-01 16:21:15,305 | INFO | Process shuting down
